2024-01-14 16:59:01,534 [DEBUG] PIL.PngImagePlugin: STREAM b'IHDR' 16 13
2024-01-14 16:59:01,534 [DEBUG] PIL.PngImagePlugin: STREAM b'sBIT' 41 4
2024-01-14 16:59:01,534 [DEBUG] PIL.PngImagePlugin: b'sBIT' 41 4 (unknown)
2024-01-14 16:59:01,534 [DEBUG] PIL.PngImagePlugin: STREAM b'sRGB' 57 1
2024-01-14 16:59:01,534 [DEBUG] PIL.PngImagePlugin: STREAM b'gAMA' 70 4
2024-01-14 16:59:01,535 [DEBUG] PIL.PngImagePlugin: STREAM b'pHYs' 86 9
2024-01-14 16:59:01,535 [DEBUG] PIL.PngImagePlugin: STREAM b'tEXt' 107 25
2024-01-14 16:59:01,535 [DEBUG] PIL.PngImagePlugin: STREAM b'IDAT' 144 34877
2024-01-14 16:59:01,591 [ERROR] root: [Errno 2] No such file or directory: 'C:\\Users\\tekin\\projects\\car_rental\\media\\attachments\\webp\\rgb.webp'
Traceback (most recent call last):
  File "C:\Users\tekin\projects\car_rental\attachment\models.py", line 75, in make_thumbnail
    self.save_webp_image()
  File "C:\Users\tekin\projects\car_rental\attachment\models.py", line 58, in save_webp_image
    image.save(fp=os.path.join(MEDIA_ROOT, "attachments", "webp", webp_name + ".webp"),
  File "C:\Users\tekin\projects\car_rental\venv\Lib\site-packages\PIL\Image.py", line 2436, in save
    fp = builtins.open(filename, "w+b")
         ^^^^^^^^^^^^^^^^^^^^^^^^^^^^^^
FileNotFoundError: [Errno 2] No such file or directory: 'C:\\Users\\tekin\\projects\\car_rental\\media\\attachments\\webp\\rgb.webp'
2024-01-14 17:02:16,529 [DEBUG] PIL.PngImagePlugin: STREAM b'IHDR' 16 13
2024-01-14 17:02:16,529 [DEBUG] PIL.PngImagePlugin: STREAM b'sBIT' 41 4
2024-01-14 17:02:16,529 [DEBUG] PIL.PngImagePlugin: b'sBIT' 41 4 (unknown)
2024-01-14 17:02:16,530 [DEBUG] PIL.PngImagePlugin: STREAM b'sRGB' 57 1
2024-01-14 17:02:16,530 [DEBUG] PIL.PngImagePlugin: STREAM b'gAMA' 70 4
2024-01-14 17:02:16,530 [DEBUG] PIL.PngImagePlugin: STREAM b'pHYs' 86 9
2024-01-14 17:02:16,530 [DEBUG] PIL.PngImagePlugin: STREAM b'tEXt' 107 25
2024-01-14 17:02:16,530 [DEBUG] PIL.PngImagePlugin: STREAM b'IDAT' 144 34877
2024-01-14 17:02:16,595 [DEBUG] PIL.PngImagePlugin: STREAM b'IHDR' 16 13
2024-01-14 17:02:16,596 [DEBUG] PIL.PngImagePlugin: STREAM b'sBIT' 41 4
2024-01-14 17:02:16,596 [DEBUG] PIL.PngImagePlugin: b'sBIT' 41 4 (unknown)
2024-01-14 17:02:16,596 [DEBUG] PIL.PngImagePlugin: STREAM b'sRGB' 57 1
2024-01-14 17:02:16,596 [DEBUG] PIL.PngImagePlugin: STREAM b'gAMA' 70 4
2024-01-14 17:02:16,597 [DEBUG] PIL.PngImagePlugin: STREAM b'pHYs' 86 9
2024-01-14 17:02:16,597 [DEBUG] PIL.PngImagePlugin: STREAM b'tEXt' 107 25
2024-01-14 17:02:16,597 [DEBUG] PIL.PngImagePlugin: STREAM b'IDAT' 144 34877
2024-01-14 22:27:36,445 [ERROR] root: Field 'id' expected a number but got <SimpleLazyObject: <django.contrib.auth.models.AnonymousUser object at 0x0000029A74764490>>.
Traceback (most recent call last):
  File "C:\Users\tekin\projects\car_rental\venv\Lib\site-packages\django\db\models\fields\__init__.py", line 2112, in get_prep_value
    return int(value)
           ^^^^^^^^^^
TypeError: int() argument must be a string, a bytes-like object or a real number, not 'SimpleLazyObject'

The above exception was the direct cause of the following exception:

Traceback (most recent call last):
  File "C:\Users\tekin\projects\car_rental\frontend\views.py", line 254, in get
    Token.objects.filter(user=request.user).delete()
    ^^^^^^^^^^^^^^^^^^^^^^^^^^^^^^^^^^^^^^^
  File "C:\Users\tekin\projects\car_rental\venv\Lib\site-packages\django\db\models\manager.py", line 87, in manager_method
    return getattr(self.get_queryset(), name)(*args, **kwargs)
           ^^^^^^^^^^^^^^^^^^^^^^^^^^^^^^^^^^^^^^^^^^^^^^^^^^^
  File "C:\Users\tekin\projects\car_rental\venv\Lib\site-packages\django\db\models\query.py", line 1476, in filter
    return self._filter_or_exclude(False, args, kwargs)
           ^^^^^^^^^^^^^^^^^^^^^^^^^^^^^^^^^^^^^^^^^^^^
  File "C:\Users\tekin\projects\car_rental\venv\Lib\site-packages\django\db\models\query.py", line 1494, in _filter_or_exclude
    clone._filter_or_exclude_inplace(negate, args, kwargs)
  File "C:\Users\tekin\projects\car_rental\venv\Lib\site-packages\django\db\models\query.py", line 1501, in _filter_or_exclude_inplace
    self._query.add_q(Q(*args, **kwargs))
  File "C:\Users\tekin\projects\car_rental\venv\Lib\site-packages\django\db\models\sql\query.py", line 1602, in add_q
    clause, _ = self._add_q(q_object, self.used_aliases)
                ^^^^^^^^^^^^^^^^^^^^^^^^^^^^^^^^^^^^^^^^
  File "C:\Users\tekin\projects\car_rental\venv\Lib\site-packages\django\db\models\sql\query.py", line 1634, in _add_q
    child_clause, needed_inner = self.build_filter(
                                 ^^^^^^^^^^^^^^^^^^
  File "C:\Users\tekin\projects\car_rental\venv\Lib\site-packages\django\db\models\sql\query.py", line 1548, in build_filter
    condition = self.build_lookup(lookups, col, value)
                ^^^^^^^^^^^^^^^^^^^^^^^^^^^^^^^^^^^^^^
  File "C:\Users\tekin\projects\car_rental\venv\Lib\site-packages\django\db\models\sql\query.py", line 1378, in build_lookup
    lookup = lookup_class(lhs, rhs)
             ^^^^^^^^^^^^^^^^^^^^^^
  File "C:\Users\tekin\projects\car_rental\venv\Lib\site-packages\django\db\models\lookups.py", line 30, in __init__
    self.rhs = self.get_prep_lookup()
               ^^^^^^^^^^^^^^^^^^^^^^
  File "C:\Users\tekin\projects\car_rental\venv\Lib\site-packages\django\db\models\fields\related_lookups.py", line 156, in get_prep_lookup
    self.rhs = target_field.get_prep_value(self.rhs)
               ^^^^^^^^^^^^^^^^^^^^^^^^^^^^^^^^^^^^^
  File "C:\Users\tekin\projects\car_rental\venv\Lib\site-packages\django\db\models\fields\__init__.py", line 2114, in get_prep_value
    raise e.__class__(
TypeError: Field 'id' expected a number but got <SimpleLazyObject: <django.contrib.auth.models.AnonymousUser object at 0x0000029A74764490>>.
